<mujoco model="panda">
  <compiler angle="radian"/>
  <default/>
  <asset>
    <mesh name="link0" file="link0.stl"/>
    <mesh name="link1" file="link1.stl"/>
    <mesh name="link2" file="link2.stl"/>
    <mesh name="link3" file="link3.stl"/>
    <mesh name="link4" file="link4.stl"/>
    <mesh name="link5" file="link5.stl"/>
    <mesh name="link6" file="link6.stl"/>
    <mesh name="link7" file="link7.stl"/>
  </asset>

  <actuator>
    <motor ctrllimited="true" ctrlrange="-87 87" forcelimited="true" forcerange="-87 87" joint="panda_joint1" name="panda_joint1" />
    <motor ctrllimited="true" ctrlrange="-87 87" forcelimited="true" forcerange="-87 87" joint="panda_joint2" name="panda_joint2" />
    <motor ctrllimited="true" ctrlrange="-87 87" forcelimited="true" forcerange="-87 87" joint="panda_joint3" name="panda_joint3" />
    <motor ctrllimited="true" ctrlrange="-87 87" forcelimited="true" forcerange="-87 87" joint="panda_joint4" name="panda_joint4" />
    <motor ctrllimited="true" ctrlrange="-12 12" forcelimited="true" forcerange="-12 12" joint="panda_joint5" name="panda_joint5" />
    <motor ctrllimited="true" ctrlrange="-12 12" forcelimited="true" forcerange="-12 12" joint="panda_joint6" name="panda_joint6" />
    <motor ctrllimited="true" ctrlrange="-12 12" forcelimited="true" forcerange="-12 12" joint="panda_joint7" name="panda_joint7" />
  </actuator>

  <worldbody>
    <geom type="mesh" rgba="1 1 1 1" mesh="link0"/>
    <body name="panda_link1" pos="0 0 0.333">
      <inertial pos="0 -0.0324958 -0.0675818" quat="0.981683 0.190521 0 0" mass="2.74" diaginertia="0.0180417 0.0177996 0.00432093"/>
      <joint name="panda_joint1" pos="0 0 0" axis="0 0 1" limited="true" range="-2.8973 2.8973" frictionloss="0.1"/>
      <geom type="mesh" rgba="1 1 1 1" mesh="link1"/>
      <body name="panda_link2" pos="0 0 0" quat="0.707107 -0.707107 0 0">
        <inertial pos="0 -0.06861 0.0322285" quat="0.560713 0.82801 0 0" mass="2.74" diaginertia="0.0182856 0.0180417 0.00432333"/>
        <joint name="panda_joint2" pos="0 0 0" axis="0 0 1" limited="true" range="-1.7628 1.7628" frictionloss="0.1"/>
        <geom type="mesh" rgba="1 1 1 1" mesh="link2"/>
        <body name="panda_link3" pos="0 -0.316 0" quat="0.707107 0.707107 0 0">
          <inertial pos="0.0469893 0.0316374 -0.031704" quat="0.433045 0.206217 0.388258 0.786894" mass="2.38" diaginertia="0.0115154 0.0112025 0.00300415"/>
          <joint name="panda_joint3" pos="0 0 0" axis="0 0 1" limited="true" range="-2.8973 2.8973" frictionloss="0.1"/>
          <geom type="mesh" rgba="1 1 1 1" mesh="link3"/>
          <body name="panda_link4" pos="0.0825 0 0" quat="0.707107 0.707107 0 0">
            <inertial pos="-0.0360446 0.0336853 0.031882" quat="0.351193 0.505642 -0.17835 0.767582" mass="2.38" diaginertia="0.0118373 0.0115967 0.0030681"/>
            <joint name="panda_joint4" pos="0 0 0" axis="0 0 1" limited="true" range="-3.0718 0.0698" frictionloss="0.1"/>
            <geom type="mesh" rgba="1 1 1 1" mesh="link4"/>
            <body name="panda_link5" pos="-0.0825 0.384 0" quat="0.707107 -0.707107 0 0">
              <inertial pos="0 0.0610427 -0.104176" quat="0.701706 -0.0997778 0.0995563 0.698385" mass="2.74" diaginertia="0.0311296 0.0303714 0.00218702"/>
              <joint name="panda_joint5" pos="0 0 0" axis="0 0 1" limited="true" range="-2.8973 2.8973" frictionloss="0.1"/>
              <geom type="mesh" rgba="1 1 1 1" mesh="link5"/>
              <body name="panda_link6" pos="0 0 0" quat="0.707107 0.707107 0 0">
                <inertial pos="0.0510509 0.009108 0.0106343" quat="-0.124537 0.772521 0.109907 0.612881" mass="1.55" diaginertia="0.0057297 0.00420201 0.0027288"/>
                <joint name="panda_joint6" pos="0 0 0" axis="0 0 1" limited="true" range="-0.0175 3.7525" frictionloss="0.1"/>
                <geom type="mesh" rgba="1 1 1 1" mesh="link6"/>
                <body name="panda_link7" pos="0.088 0 0" quat="0.707107 0.707107 0 0">
                  <inertial pos="0.00524251 0.00516952 0.105839" quat="0.230606 0.303369 0.771011 0.510226" mass="0.54" diaginertia="0.00557191 0.00354547 0.00276863"/>
                  <joint name="panda_joint7" pos="0 0 0" axis="0 0 1" limited="true" range="-2.8973 2.8973" frictionloss="0.1"/>
                  <geom type="mesh" rgba="1 1 1 1" mesh="link7"/>
                  <!-- <geom pos="0 0 0.107" quat="0.92388 0 0 -0.382683" type="mesh" rgba="1 1 1 1" mesh="hand"/>
                  <body name="panda_leftfinger" pos="0 0 0.1654" quat="0.92388 0 0 -0.382683">
                    <inertial pos="0 0.0145644 0.0227941" mass="0.1" diaginertia="3.01221e-05 2.95874e-05 6.95125e-06"/>
                    <joint name="panda_finger_joint1" pos="0 0 0" axis="0 1 0" type="slide" limited="true" range="-0.001 0.04"/>
                    <geom type="mesh" rgba="1 1 1 1" mesh="finger"/>
                  </body>
                  <body name="panda_rightfinger" pos="0 0 0.1654" quat="0.92388 0 0 -0.382683">
                    <inertial pos="0 0.0145644 0.0227941" quat="0 0 0 1" mass="0.1" diaginertia="3.01221e-05 2.95874e-05 6.95125e-06"/>
                    <joint name="panda_finger_joint2" pos="0 0 0" axis="0 -1 0" type="slide" limited="true" range="-0.001 0.04"/>
                    <geom quat="0 0 0 1" type="mesh" rgba="1 1 1 1" mesh="finger"/>
                  </body> -->
                </body>
              </body>
            </body>
          </body>
        </body>
      </body>
    </body>
  </worldbody>
</mujoco>
