<mujoco model ="panda_without_gripper">
  <compiler angle="radian" 
  meshdir="../mesh/"
  texturedir="../textures/">
  </compiler>

  <asset>
      <mesh name="link0" file="link0.stl" />
      <mesh name="link1" file="link1.stl" />
      <mesh name="link2" file="link2.stl" />
      <mesh name="link3" file="link3.stl" />
      <mesh name="link4" file="link4.stl" />
      <mesh name="link5" file="link5.stl" />
      <mesh name="link6" file="link6.stl" />
      <mesh name="link7" file="link7.stl" />
      <!-- <mesh name="hand" file="hand.stl" /> -->
      <!-- <mesh name="finger" file="finger.stl" /> -->
      <texture name="panda" file="panda.png" type="2d" />
      <material name="panda" texture="panda" shininess=".4" specular=".4" />
      <material name="panda_white" rgba="1 1 1 1" shininess="0.4" specular="0.4" />

      <!-- peg -->
      <texture file="steel-scratched.png" type="cube" name="steel-metal"/>
      <texture file="brass-ambra.png" type="cube" name="brass-metal"/>
      <material name="smetal" reflectance="1.0" shininess="1.0" specular="1.0" texrepeat="1 1" texture="steel-metal" texuniform="true"/>
      <material name="bmetal"  reflectance="1.0" shininess="1.0" specular="1.0" texrepeat="1 1" texture="brass-metal" texuniform="true"/>
    </asset>

    <worldbody>
      <body name="panda_link0">
        <geom type="mesh" material="panda" mesh="link0" />
        <!-- 动力学参数 -->
        <inertial pos="-4.1018e-02 -1.4e-04 4.9974e-02" mass="2.91242" fullinertia="3.15e-03 3.88e-03 4.285e-03 8.2904e-07 1.5e-04 8.2299e-06" />
        <!-- 文章的动力学参数 -->
        <!-- <inertial pos="-4.1018e-02 -1.4e-04 4.9974e-02" mass="6.29769e-01" fullinertia="3.15e-03 3.88e-03 4.285e-03 8.2904e-07 1.5e-04 8.2299e-06" /> -->
        <body name="panda_link1" pos="0 0 0.333">
          <inertial pos="0 -0.0324874 -0.0675913" quat="0.984906 0.17309 0 0" mass="2.48586" diaginertia="0.016656 0.0164288 0.00398832" />
          <!-- <inertial pos="3.875e-03 2.081e-03 -4.762e-02" mass="4.970684" fullinertia="7.0337e-01 7.0661e-01 9.1170e-03 -1.3900e-04 6.7720e-03 1.9169e-02" /> -->
          <!-- <joint name="panda_joint1" pos="0 0 0" axis="0 0 1" limited="true" range="-2.8973 2.8973" damping="0.0665" frictionloss="0.2450" /> -->
          <joint name="panda_joint1" pos="0 0 0" axis="0 0 1" limited="true" range="-2.8973 2.8973" damping="0.01" frictionloss="0.2450" />
          <geom type="mesh" material="panda_white" mesh="link1" />
          <body name="panda_link2" pos="0 0 0" quat="0.707107 -0.707107 0 0">
            <inertial pos="-0.00478824 -0.0746218 0.0342176" quat="0.612068 0.789571 -0.0403795 0.0178969" mass="2.96425" diaginertia="0.0147346 0.0144296 0.00413597" />
            <!-- <inertial pos="-3.141e-03 -2.872e-02 3.495e-03" mass="0.646926" fullinertia="7.9620e-03 2.8110e-02 2.5995e-02 -3.9250e-03 1.0254e-02 7.0400e-04" /> -->
            <!-- <joint name="panda_joint2" pos="0 0 0" axis="0 0 1" limited="true" range="-1.7628 1.7628" damping="0.1987" frictionloss="0.1523" /> -->
            <joint name="panda_joint2" pos="0 0 0" axis="0 0 1" limited="true" range="-1.7628 1.7628" damping="0.01" frictionloss="0.1523" />
            <geom type="mesh" material="panda_white" mesh="link2" />
            <body name="panda_link3" pos="0 -0.316 0" quat="0.707107 0.707107 0 0">
              <inertial pos="0.0430423 0.029605 -0.0282414" quat="0.438574 0.199348 0.368245 0.795179" mass="2.48764" diaginertia="0.0112147 0.0108071 0.0028102" />
              <!-- <inertial pos="2.7518e-02 3.9252e-02 -6.6502e-02" mass="3.228604" fullinertia="3.7242e-02 3.6155e-02 1.0830e-02 -4.7610e-03 -1.1396e-02 -1.2805e-02" /> -->
              <!-- <joint name="panda_joint3" pos="0 0 0" axis="0 0 1" limited="true" range="-2.8973 2.8973" damping="0.0399" frictionloss="0.1827" /> -->
              <joint name="panda_joint3" pos="0 0 0" axis="0 0 1" limited="true" range="-2.8973 2.8973" damping="0.01" frictionloss="0.1827" />
              <geom type="mesh" material="panda" mesh="link3" />
              <body name="panda_link4" pos="0.0825 0 0" quat="0.707107 0.707107 0 0">
                <inertial pos="-0.0333784 0.0491476 0.0239849" quat="0.38689 0.541483 -0.159765 0.7291" mass="2.00746" diaginertia="0.00794987 0.00763422 0.00296007" />
                <!-- <inertial pos="-5.317e-02 1.04419e-01 2.7454e-02" mass="3.587895" fullinertia="2.5853e-02 1.9552e-02 2.8323e-02 7.7960e-03 -1.3320e-03 8.6410e-03" /> -->
                <!-- <joint name="panda_joint4" pos="0 0 0" axis="0 0 1" limited="true" range="-3.0718 -0.0698" damping="0.2257" frictionloss="0.3591" /> -->
                <joint name="panda_joint4" pos="0 0 0" axis="0 0 1" limited="true" range="-3.0718 -0.0698" damping="0.01" frictionloss="0.3591" />
                <geom type="mesh" material="panda" mesh="link4" />
                <body name="panda_link5" pos="-0.0825 0.384 0" quat="0.707107 -0.707107 0 0">
                  <inertial pos="-0.000235444 0.0541427 -0.110191" quat="0.67022 -0.115808 0.0963565 0.726711" mass="2.04554" diaginertia="0.0279657 0.0273088 0.00202938" />
                  <!-- <inertial pos="1.1953e-02 4.1065e-02 -3.8437e-02" mass="1.225946" fullinertia="3.5549e-02 2.9474e-02 8.6270e-03 -2.1170e-03 -4.0370e-03 2.2900e-04" /> -->
                  <!-- <joint name="panda_joint5" pos="0 0 0" axis="0 0 1" limited="true" range="-2.8973 2.8973" damping="0.1023" frictionloss="0.2669" /> -->
                  <joint name="panda_joint5" pos="0 0 0" axis="0 0 1" limited="true" range="-2.8973 2.8973" damping="0.01" frictionloss="0.2669" />
                  <geom type="mesh" material="panda" mesh="link5" />
                  <body name="panda_link6" pos="0 0 0" quat="0.707107 0.707107 0 0">
                    <inertial pos="0.0432801 -0.00928474 0.0113491" quat="-0.0963598 0.787327 0.056939 0.606291" mass="2.24648" diaginertia="0.00483453 0.00360784 0.00238753" />
                    <!-- <inertial pos="6.0149e-02 -1.4117e-02 -1.0517e-02" mass="1.666555 " fullinertia="1.9640e-03 4.3540e-03 5.4330e-03 1.0900e-04 -1.1580e-03 3.4100e-04" /> -->
                    <!-- <joint name="panda_joint6" pos="0 0 0" axis="0 0 1" limited="true" range="-0.0175 3.7525" damping="-0.0132" frictionloss="0.1658" /> -->
                    <joint name="panda_joint6" pos="0 0 0" axis="0 0 1" limited="true" range="-0.0175 3.7525" damping="-0.01" frictionloss="0.1658" />
                    <geom type="mesh" material="panda" mesh="link6" />
                    <body name="panda_link7" pos="0.088 0 0" quat="0.707107 0.707107 0 0">
                      <inertial pos="0.00484795 0.00253058 0.0652015" quat="0.880947 -0.232664 -0.0503827 -0.408976" mass="0.677569" diaginertia="0.000981968 0.000748071 0.00065087" />
                      <!-- <inertial pos="1.0517e-02 -4.252e-03 6.1597e-02" mass="7.35522e-01" fullinertia="1.2516e-02 1.0027e-02 4.8150e-03 -4.2800e-04 -1.1960e-03 -7.4100e-04" /> -->
                      <!-- <joint name="panda_joint7" pos="0 0 0" axis="0 0 1" limited="true" range="-2.8973 2.8973" damping="0.0638" frictionloss="1.2109" /> -->
                      <joint name="panda_joint7" pos="0 0 0" axis="0 0 1" limited="true" range="-2.8973 2.8973" damping="0.01" frictionloss="1.2109" />
                      <geom type="mesh" material="panda" mesh="link7" />

                      <!-- box peg -->
                      <!-- <body name="" pos="0 0 0.207">
                        <geom pos="0 0 -0.05" size="0.016 0.016 0.05" type="box" group="0" friction="1 0.005 0.0001" mass="0.05"/>
                        <geom pos="0 0 -0.05" size="0.016 0.016 0.05" type="box" conaffinity="0" contype="0" group="1" material="bmetal" />
                        <body name="tip" pos="0 0 0.05"></body>
                      </body> -->
                    <!-- cylinder peg -->
                      <!-- <body name="peg" pos="0 0 0.207">
                        <site name="sensor_site" pos="0 0 -0.10" size="0.01 0.01 0.01" type="box" />
                        <geom pos="0 0 -0.05" size="0.019 0.05" type="cylinder" group="0" friction="1 0.005 0.0001" mass="0.05" name="peg_collision"/>
                        <geom pos="0 0 -0.05" size="0.019 0.05" type="cylinder" conaffinity="0" contype="0" group="1" material="smetal" />
                        <body name="tip" euler="0 0 -0.785398163397"></body>
                      </body>
                       -->
                      <!-- End Effector attaches here-->
                    </body>
                  </body>
                </body>
              </body>
            </body>
          </body>
        </body>
      </body>
    </worldbody>

  <sensor>
      <jointpos name="fr_arm_jp1" joint="panda_joint1"/>
      <jointpos name="fr_arm_jp2" joint="panda_joint2"/>
      <jointpos name="fr_arm_jp3" joint="panda_joint3"/>
      <jointpos name="fr_arm_jp4" joint="panda_joint4"/>
      <jointpos name="fr_arm_jp5" joint="panda_joint5"/>
      <jointpos name="fr_arm_jp6" joint="panda_joint6"/>
      <jointpos name="fr_arm_jp7" joint="panda_joint7"/>
      <jointvel name="fr_arm_jv1" joint="panda_joint1"/>
      <jointvel name="fr_arm_jv2" joint="panda_joint2"/>
      <jointvel name="fr_arm_jv3" joint="panda_joint3"/>
      <jointvel name="fr_arm_jv4" joint="panda_joint4"/>
      <jointvel name="fr_arm_jv5" joint="panda_joint5"/>
      <jointvel name="fr_arm_jv6" joint="panda_joint6"/>
      <jointvel name="fr_arm_jv7" joint="panda_joint7"/>
      <!-- <force name="peg_force" site="sensor_site"/>
      <torque name="peg_torque" site="sensor_site"/> -->
      <!-- <rangefinder name="success_check" site="hole_bottom" /> -->
  </sensor>

      <actuator>
      <motor ctrllimited="true" ctrlrange="-87 87" forcelimited="true" forcerange="-87 87" joint="panda_joint1" name="panda_joint1" />
      <motor ctrllimited="true" ctrlrange="-87 87" forcelimited="true" forcerange="-87 87" joint="panda_joint2" name="panda_joint2" />
      <motor ctrllimited="true" ctrlrange="-87 87" forcelimited="true" forcerange="-87 87" joint="panda_joint3" name="panda_joint3" />
      <motor ctrllimited="true" ctrlrange="-87 87" forcelimited="true" forcerange="-87 87" joint="panda_joint4" name="panda_joint4" />
      <motor ctrllimited="true" ctrlrange="-12 12" forcelimited="true" forcerange="-12 12" joint="panda_joint5" name="panda_joint5" />
      <motor ctrllimited="true" ctrlrange="-12 12" forcelimited="true" forcerange="-12 12" joint="panda_joint6" name="panda_joint6" />
      <motor ctrllimited="true" ctrlrange="-12 12" forcelimited="true" forcerange="-12 12" joint="panda_joint7" name="panda_joint7" />
    </actuator>

</mujoco>
